Workbook

Sheet Resumo
B2: % de conslusão do projeto | H2: =SUM(H5:H14) -> 37.175741
B4: Meta | C4: Descrição | D4: Valor aprovado | E4: Situação | F4: % concluída | G4: Peso | H4: % projeto
B5: Meta 1 | C5: Realizar diagnóstico técnico e produtivo das comunidades atendidas, com ênfase na caracterização dos arranjos produtivos locais. | D5: 251000 | E5: =IF(F5 = 0, "Não iniciado", IF(F5 < 100, "Em execução", "Concluída")) -> Em execução | F5: ='M1'!H1 -> 1.0083333 | G5: 30 | H5: =F5*G5 -> 30.25
B6: Meta 2 | C6: Fortalecer as associações rurais como instâncias organizadoras da produção, da assistência técnica e da gestão de equipamentos. | D6: 595000 | E6: =IF(F6 = 0, "Não iniciado", IF(F6 < 100, "Em execução", "Concluída")) -> Não iniciado | F6: ='M2'!G1 -> 0 | G6: 5 | H6: =F6*G6 -> 0
B7: Meta 3 | C7: Identificar os principais fatores edáficos que limitam a produtividade e recomendar práticas de manejo e conservação do solo. | D7: 3212000 | E7: =IF(F7 = 0, "Não iniciado", IF(F7 < 100, "Em execução", "Concluída")) -> Em execução | F7: ='M3'!H1 -> 0.13005 | G7: 25 | H7: =F7*G7 -> 3.25125
B8: Meta 4 | C8: Adquirir e entregar máquinas, insumos e implementos agrícolas básicos, com base nas demandas priorizadas pelos diagnósticos locais. | D8: 45000000 | E8: =IF(F8 = 0, "Não iniciado", IF(F8 < 100, "Em execução", "Concluída")) -> Em execução | F8: ='M4'!F1 -> 0.2 | G8: 10 | H8: =F8*G8 -> 2
B9: Meta 5 | C9: Prestar assessoria técnica a produtores rurais associados durante a execução do projeto. | D9: 350000 | E9: =IF(F9 = 0, "Não iniciado", IF(F9 < 100, "Em execução", "Concluída")) -> Não iniciado | F9: ='M5'!G1 -> 0 | G9: 10 | H9: =F9*G9 -> 0
B10: Meta 6 | C10: Capacitar agricultores em tecnologias apropriadas e práticas sustentáveis de uso do solo e produção agropecuária | D10: 471000 | E10: =IF(F10 = 0, "Não iniciado", IF(F10 < 100, "Em execução", "Concluída")) -> Não iniciado | F10: ='M6'!G1 -> 0 | G10: 10 | H10: =F10*G10 -> 0
B11: Meta 7 | C11: Envolver estudantes dos cursos superiores das ciências agrárias em atividades práticas de extensão no projeto. | D11: 295600 | E11: =IF(F11 = 0, "Não iniciado", IF(F11 < 100, "Em execução", "Concluída")) -> Não iniciado | F11: ='M7'!F1 -> 0 | G11: 3 | H11: =F11*G11 -> 0
B12: Meta 8 | C12: Desenvolver e fomentar tecnologias aplicadas aos arranjos produtivos locais atendidos. | D12: 609400 | E12: =IF(F12 = 0, "Não iniciado", IF(F12 < 100, "Em execução", "Concluída")) -> Em execução | F12: ='M8'!K1 -> 0.05 | G12: 5 | H12: =F12*G12 -> 0.25
B13: Meta 9 | C13: Administrar e gerir eficientemente o recurso | D13: 3245000 | E13: =IF(F13 = 0, "Não iniciado", IF(F13 < 100, "Em execução", "Concluída")) -> Em execução | F13: ='M9'!C1 -> 0.42449133 | G13: 1 | H13: =F13*G13 -> 0.42449133
B14: Meta 10 | C14: Nomear, contratar e capacitar equipe de coordenadores para condução do projeto | D14: 971000 | E14: =IF(F14 = 0, "Não iniciado", IF(F14 < 100, "Em execução", "Concluída")) -> Em execução | F14: ='M10'!C1 -> 1 | G14: 1 | H14: =F14*G14 -> 1
D15: =SUM(D5:D14) -> 55000000 | G15: =SUM(G5:G14) -> 100 | H15: =SUM(H5:H14) -> 37.175741

Sheet M1
A1: Meta 1 | B1: Realizar diagnóstico técnico e produtivo das comunidades atendidas, com ênfase na caracterização dos arranjos produtivos locais. | H1: =SUM(C7:E7, H7) / 100 -> 1.0083333
A2: Diagnóstico de pelo menos 100 associações. 3 relatórios técnico-participativo elaborados.
A4: Diagnóstico de pelo menos 100 associações. | G4: 3 relatórios técnico-participativo elaborados.
A5: Quantidade prevista | C5: 100 | D5: 100 | E5: 100 | G5: Quantidade prevista | H5: 3
A6: Quantidade executada | C6: =COUNTA(A10:A109) -> 100 | D6: =COUNTA(D10:D1000) -> 125 | E6: =COUNTA(E10:E1000) -> 125 | G6: Quantidade executada | H6: =COUNTA(H10:H1001) -> 2
A7: Porcentagem executada | C7: =(C6 * C8) / C5 -> 50 | D7: =(D6 * D8) / D5 -> 18.75 | E7: =(E6 * E8) / E5 -> 18.75 | G7: Porcentagem executada | H7: =(H6 * H8) / H5 -> 13.333333
A8: Peso | C8: 50 | D8: 15 | E8: 15 | G8: Peso | H8: 20
A9: Associação | B9: Município | C9: Levantamento de campo realizado? | D9: Informações Sistematizadas? | E9: Demandas prioritárias identificadas? | G9: Relatório | H9: Relatório Elaborado?
A10: ASPROMEP | C10: Sim | D10: Sim | E10: Sim | G10: RELATÓRIO 01 | H10: Sim
A11: ACLOLICAM | C11: Sim | D11: Sim | E11: Sim | G11: RELATÓRIO 02 | H11: Sim
A12: ARME | C12: Sim | D12: Sim | E12: Sim | G12: RELATÓRIO 03
A13: ACRZS | C13: Sim | D13: Sim | E13: Sim
A14: APRERBRAL | C14: Sim | D14: Sim | E14: Sim
A15: CISAN | C15: Sim | D15: Sim | E15: Sim
A16: ASPRUB | C16: Sim | D16: Sim | E16: Sim
A17: CISAN ASPROPALMAS | C17: Sim | D17: Sim | E17: Sim
A18: ASPRUFAVI | C18: Sim | D18: Sim | E18: Sim
A19: AGRILANÇA | C19: Sim | D19: Sim | E19: Sim
A20: ASPROMOGG | C20: Sim | D20: Sim | E20: Sim
A21: BEM-TE-VI | C21: Sim | D21: Sim | E21: Sim
A22: RENASCER | C22: Sim | D22: Sim | E22: Sim
A23: CAFÉ D'ARC | C23: Sim | D23: Sim | E23: Sim
A24: ASPRONÚCLEO | C24: Sim | D24: Sim | E24: Sim
... A134: APCSA | C134: Sim | D134: Sim | E134: Sim

Sheet M2
A1: Meta 2 | B1: Fortalecer as associações rurais como instâncias organizadoras da produção, da assistência técnica e da gestão de equipamentos. | G1: =SUM(C7,G7) / 100 -> 0
A2: 50 associações parceiras formalizadas. 50 planos de gestão de equipamentos elaborados.
A4: 50 associações parceiras formalizadas. | E4: 50 planos de gestão de equipamentos elaborados.
A5: Quantidade prevista | C5: 50 | E5: Quantidade prevista | G5: 500
A6: Quantidade executada | C6: =COUNTA(C10:C951) -> 0 | E6: Quantidade executada | G6: =COUNTA(G10:G951) -> 0
A7: Porcentagem executada | C7: =(C6 * C8) / C5 -> 0 | E7: Porcentagem executada | G7: =(G6 * G8) / G5 -> 0
A8: Peso | C8: 50 | E8: Peso | G8: 50
A9: Associação | B9: Município | C9: Parceria operacional formalizada? | E9: Associação | F9: Município | G9: Plano de gestão de equipamentos elaborado?
A10: ASSOCIAÇÃO 01 | E10: ASSOCIAÇÃO 01
A11: ASSOCIAÇÃO 02 | E11: ASSOCIAÇÃO 02
A12: ASSOCIAÇÃO 03 | E12: ASSOCIAÇÃO 03
A13: ASSOCIAÇÃO 04 | E13: ASSOCIAÇÃO 04
A14: ASSOCIAÇÃO 05 | E14: ASSOCIAÇÃO 05
A15: ASSOCIAÇÃO 06 | E15: ASSOCIAÇÃO 06
A16: ASSOCIAÇÃO 07 | E16: ASSOCIAÇÃO 07
A17: ASSOCIAÇÃO 08 | E17: ASSOCIAÇÃO 08
A18: ASSOCIAÇÃO 09 | E18: ASSOCIAÇÃO 09
A19: ASSOCIAÇÃO 10 | E19: ASSOCIAÇÃO 10
A20: ASSOCIAÇÃO 11 | E20: ASSOCIAÇÃO 11
A21: ASSOCIAÇÃO 12 | E21: ASSOCIAÇÃO 12
... A59: ASSOCIAÇÃO 50 | E59: ASSOCIAÇÃO 50

Sheet M3
A1: Meta 3 | B1: Identificar os principais fatores edáficos que limitam a produtividade e recomendar práticas de manejo e conservação do solo. | H1: =SUM(C7:D7, H7) / 100 -> 0.13005
A2: 5.000 análises laboratoriais realizadas prioritariamente no laboratório de solos do IFRO ou em parceiros externos. 1.000 laudos com recomendações entregues.
A4: 5.000 análises laboratoriais realizadas. | F4: 1.000 laudos com recomendações entregues.
A5: Quantidade prevista | C5: 5000 | D5: 5000 | F5: Quantidade prevista | H5: 1000
A6: Quantidade executada | C6: =COUNTA(C10:C5025) -> 1018 | D6: =COUNTA(D10:D1001) -> 565 | F6: Quantidade executada | H6: =COUNTA(F10:F1001) -> 0
A7: Porcentagem executada | C7: =(C6 * C8) / C5 -> 10.18 | D7: =(D6 * D8) / D5 -> 2.825 | F7: Porcentagem executada | H7: =(H6 * H8) / H5 -> 0
A8: Peso | C8: 50 | D8: 25 | F8: Peso | H8: 25
A9: Propriedade | B9: Associação | C9: Coleta Realizada? | D9: Análise realizada? | F9: Propriedade | G9: Associação | H9: Recomendações Emitidas?
A10: José De Assis Costa | B10: ASPROMEP | C10: Sim | D10: Sim
A11: José Conceição | B11: ASPROMEP | C11: Sim | D11: Sim
A12: José Conceição | B12: ASPROMEP | C12: Sim | D12: Sim
A13: José Conceição | B13: ASPROMEP | C13: Sim | D13: Sim
A14: Ezequiel Antune de castro | B14: ASPROMEP | C14: Sim | D14: Sim
A15: Elivelton Goes da Silva | B15: ASPROMEP | C15: Sim | D15: Sim
A16: Neusa Matilde de Oliveira | B16: Boa Safra | C16: Sim | D16: Sim
A17: Edivaldo Felix Batista | B17: Boa Safra | C17: Sim | D17: Sim
A18: Antônio Alesandro Silva | B18: Boa Safra | C18: Sim | D18: Sim
A19: Francisco Elias | B19: Boa Safra | C19: Sim | D19: Sim
A20: Francisco Elias | B20: Boa Safra | C20: Sim | D20: Sim
A21: José Antonio da Silva | B21: ACRUB | C21: Sim | D21: Sim
... A23: Eugênio Cavilia | B23: ACRUB | C23: Sim | D23: Sim
A24: Sergio Berkhamm | B24: ACRUB | C24: Sim
A25: Joaquim Antonio de amorim | B25: ACRUB | C25: Sim | D25: Sim
A26: Joaquim Antonio de amorim | B26: ACRUB | C26: Sim | D26: Sim
A27: Francisca Vanderleia de Souza | B27: ASPRONA | C27: Sim | D27: Sim
A28: Sandra Maria Hesketh | B28: ASPRONA | C28: Sim | D28: Sim
A29: Helena Maria Antunes | B29: ASPRONA | C29: Sim | D29: Sim
A30: Helena Maria Antunes | B30: ASPRONA | C30: Sim | D30: Sim
A31: Associação rural nova aliança | B31: ASPRONA | C31: Sim
A32: Ernandi Ramiro | B32: APRERBAL | C32: Sim
A33: Derly Alves Teixeira | B33: APRERBAL | C33: Sim | D33: Sim
A34: Renan Oliveira | B34: APRERBAL | C34: Sim | D34: Sim
A35: Altair de Jesus | B35: APRERBAL | C35: Sim | D35: Sim
A36: José Raimundo Pinheiro | B36: APRERBAL | C36: Sim | D36: Sim
A37: Renan Oliveira | B37: APRERBAL | C37: Sim | D37: Sim
A38: Gecildo Santiago | B38: APRERBAL | C38: Sim | D38: Sim
A39: Edilson Nunes | B39: APRERBAL | C39: Sim | D39: Sim
A40: José Almir Leandro Da Silva | B40: APRERBAL | C40: Sim | D40: Sim
A41: Estefano Futerko | B41: APRERBAL | C41: Sim | D41: Sim
A42: Edmilson Ribeiro Oliveira | B42: ASCLAPF | C42: Sim
...

Sheet M4
A1: Meta 4 | B1: Adquirir e entregar máquinas, insumos e implementos agrícolas básicos, com base nas demandas priorizadas pelos diagnósticos locais | F1: =SUM(C7:F7) / 100 -> 0.2
A2: 100 kits/equipamentos entregues.
A4: 100 kits/equipamentos entregues.
A5: Quantidade prevista | C5: 100 | D5: 100 | E5: 100 | F5: 100
A6: Quantidade executada | C6: =COUNTA(C10:C1001) -> 100 | D6: =COUNTA(D10:D1001) -> 0 | E6: =COUNTA(E10:E1001) -> 0 | F6: =COUNTA(F10:F1001) -> 0
A7: Porcentagem executada | C7: =(C6 * C8) / C5 -> 20 | D7: =(D6 * D8) / D5 -> 0 | E7: =(E6 * E8) / E5 -> 0 | F7: =(F6 * F8) / F5 -> 0
A8: Peso | C8: 20 | D8: 50 | E8: 15 | F8: 15
A9: Associação | B9: Município | C9: Levantamento de demanda realizado? | D9: Compra realizada? | E9: Termo de uso elaborado? | F9: Entrega realizada?
A10: ASSOCIAÇÃO 01 | C10: 45748
A11: ASSOCIAÇÃO 02 | C11: 45749
A12: ASSOCIAÇÃO 03 | C12: 45750
A13: ASSOCIAÇÃO 04 | C13: 45751
A14: ASSOCIAÇÃO 05 | C14: 45752
A15: ASSOCIAÇÃO 06 | C15: 45753
A16: ASSOCIAÇÃO 07 | C16: 45754
A17: ASSOCIAÇÃO 08 | C17: 45755
A18: ASSOCIAÇÃO 09 | C18: 45756
A19: ASSOCIAÇÃO 10 | C19: 45757
A20: ASSOCIAÇÃO 11 | C20: 45758
A21: ASSOCIAÇÃO 12 | C21: 45759
... A109: ASSOCIAÇÃO 100 | C109: 45847

Sheet M5
A1: Meta 5 | B1: Prestar assessoria técnica a produtores rurais associados durante a execução do projeto. | G1: =SUM(C7,G7) / 100 -> 0
A2: 500 atendimentos registrados. 200 visitas de retorno documentadas.
A4: 500 atendimentos registrados. | E4: 200 visitas de retorno documentadas.
A5: Quantidade prevista | C5: 500 | E5: Quantidade prevista | G5: 200
A6: Quantidade executada | C6: =COUNTA(C10:C1001) -> 0 | E6: Quantidade executada | G6: =COUNTA(G10:G1001) -> 0
A7: Porcentagem executada | C7: =(C6 * C8) / C5 -> 0 | E7: Porcentagem executada | G7: =(G6 * G8) / G5 -> 0
A8: Peso | C8: 50 | E8: Peso | G8: 50
A9: Propriedade | B9: Associação | C9: Atendimento Realizado? | E9: Propriedade | F9: Associação | G9: Visita documentada?
A10: PROPRIEDADE 01 | E10: PROPRIEDADE 01
A11: PROPRIEDADE 02 | E11: PROPRIEDADE 02
A12: PROPRIEDADE 03 | E12: PROPRIEDADE 03
A13: PROPRIEDADE 04 | E13: PROPRIEDADE 04
A14: PROPRIEDADE 05 | E14: PROPRIEDADE 05
A15: PROPRIEDADE 06 | E15: PROPRIEDADE 06
A16: PROPRIEDADE 07 | E16: PROPRIEDADE 07
A17: PROPRIEDADE 08 | E17: PROPRIEDADE 08
A18: PROPRIEDADE 09 | E18: PROPRIEDADE 09
A19: PROPRIEDADE 10 | E19: PROPRIEDADE 10

Sheet M6
A1: Meta 6 | B1: Capacitar agricultores em tecnologias apropriadas e práticas sustentáveis de uso do solo e produção agropecuária. | G1: =SUM(C7,G7) / 100 -> 0 | H1: Divergência entre projeto e plano trabalho
A2: 50 eventos formativos realizados. 500 agricultores capacitados.
A4: 50 eventos formativos realizados. | E4: 500 agricultores capacitados.
A5: Quantidade prevista | C5: 50 | E5: Quantidade prevista | G5: 500
A6: Quantidade executada | C6: =COUNTA(C10:C951) -> 0 | E6: Quantidade executada | G6: =COUNTA(G10:G951) -> 0
A7: Porcentagem executada | C7: =(C6 * C8) / C5 -> 0 | E7: Porcentagem executada | G7: =(G6 * G8) / G5 -> 0
A8: Peso | C8: 50 | E8: Peso | G8: 50
A9: Evento | B9: Associação | C9: Evento realizado? | E9: Nome | F9: Associação | G9: Capacitação realizada?
A10: EVENTO 01 | E10: PRODUTOR 01
A11: EVENTO 02 | E11: PRODUTOR 02
A12: EVENTO 03 | E12: PRODUTOR 03
A13: EVENTO 04 | E13: PRODUTOR 04
A14: EVENTO 05 | E14: PRODUTOR 05
A15: EVENTO 06 | E15: PRODUTOR 06
A16: EVENTO 07 | E16: PRODUTOR 07
A17: EVENTO 08 | E17: PRODUTOR 08
A18: EVENTO 09 | E18: PRODUTOR 09
A19: EVENTO 10 | E19: PRODUTOR 10

Sheet M7
A1: Meta 7 | B1: Envolver estudantes dos cursos superiores das ciências agrárias em atividades práticas de extensão no projeto. | F1: =SUM(C7,F7) / 100 -> 0 | G1: Divergência entre projeto e plano trabalho
A2: 10 estudantes envolvidos. 10 relatórios técnicos ou resumos científicos produzidos.
A4: 10 estudantes envolvidos. | E4: 10 relatórios técnicos ou resumos científicos produzidos.
A5: Quantidade prevista | C5: 10 | E5: Quantidade prevista | F5: 10
A6: Quantidade executada | C6: =COUNTA(C10:C1001) -> 0 | E6: Quantidade executada | F6: =COUNTA(F10:F1001) -> 0
A7: Porcentagem executada | C7: =(C6 * C8) / C5 -> 0 | E7: Porcentagem executada | F7: =(F6 * F8) / F5 -> 0
A8: Peso | C8: 50 | E8: Peso | F8: 50
A9: Aluno | B9: Atividade | C9: Contratação realizada? | E9: Relatório técnico/resumo ciêntífico | F9: Relatório produzido?
A10: ALUNO 01 | E10: RELATÓRIO 01
A11: ALUNO 02 | E11: RELATÓRIO 02
A12: ALUNO 03 | E12: RELATÓRIO 03
A13: ALUNO 04 | E13: RELATÓRIO 04
A14: ALUNO 05 | E14: RELATÓRIO 05
A15: ALUNO 06 | E15: RELATÓRIO 06
A16: ALUNO 07 | E16: RELATÓRIO 07
A17: ALUNO 08 | E17: RELATÓRIO 08
A18: ALUNO 09 | E18: RELATÓRIO 09
A19: ALUNO 10 | E19: RELATÓRIO 10

Sheet M8
A1: Meta 8 | H1: Desenvolver e fomentar tecnologias aplicadas aos arranjos produtivos locais atendidos. | K1: =SUM(B7:H7,K7) / 100 -> 0.05
A2: 2 ferramentas de TICs desenvolvidas. 6 relatórios de projetos de pesquisa entregues.
A4: 2 ferramentas de TICs desenvolvidas. | J4: 6 relatórios de projetos de pesquisa entregues.
A5: Quantidade prevista | B5: 2 | C5: 2 | D5: 2 | E5: 2 | F5: 2 | G5: 2 | H5: 2 | J5: Quantidade prevista | K5: 6
A6: Quantidade executada | B6: =COUNTA(B10:B18) -> 1 | C6: =COUNTA(C10:C18) -> 0 | D6: =COUNTA(D10:D18) -> 0 | E6: =COUNTA(E10:E18) -> 0 | F6: =COUNTA(F10:F18) -> 0 | G6: =COUNTA(G10:G18) -> 0 | H6: =COUNTA(H10:H18) -> 0 | J6: Quantidade executada | K6: =COUNTA(K10:K1001) -> 0
A7: Porcentagem executada | B7: =(B6 * B8) / B5 -> 5 | C7: =(C6 * C8) / C5 -> 0 | D7: =(D6 * D8) / D5 -> 0 | E7: =(E6 * E8) / E5 -> 0 | F7: =(F6 * F8) / F5 -> 0 | G7: =(G6 * G8) / G5 -> 0 | H7: =(H6 * H8) / H5 -> 0 | J7: Porcentagem executada | K7: =(K6 * K8) / K5 -> 0
A8: Peso | B8: 10 | C8: 10 | D8: 10 | E8: 20 | F8: 30 | G8: 5 | H8: 5 | J8: Peso | K8: 10
A9: Ferramenta | B9: Proposta apresentada? | C9: DEV Modelagem de dados | D9: DEV API | E9: DEV Frontend Web | F9: DEV App Mobile | G9: Ferramenta Implantada? | H9: capacitação realizada? | J9: Relatório técnico/resumo ciêntífico | K9: Relatório produzido?
A10: App Da Nossa Terra Rondônia | B10: 1 | J10: RELATÓRIO 01
A11: FERRAMENTA 02 | J11: RELATÓRIO 02
J12: RELATÓRIO 03
J13: RELATÓRIO 04
J14: RELATÓRIO 05
J15: RELATÓRIO 06

Sheet M9
A1: Meta 9 | B1: Administrar e gerir eficientemente o recurso | C1: =((B7 * 100)/B6) /100 -> 0.42449133
A2: Executar todo o recurso disponível.
A4: Descrição | B4: Valor
A6: Total liberado | B6: 29019319
A7: Total utilizado | B7: 12318449

Sheet M10
A1: Meta 10 | B1: Nomear, contratar e capacitar equipe de coordenadores para condução do projeto | C1: =SUM(C7) / 100 -> 1
A2: Contratarar até 6 coordenadores.
A4: Contratarar até 6 coordenadores.
A5: Quantidade prevista | C5: 6
A6: Quantidade executada | C6: =COUNTA(C10:C905) -> 6
A7: Porcentagem executada | C7: =(C6 * C8) / C5 -> 100
A8: Peso | C8: 100
A9: Nome | B9: Função | C9: Contratação realizada?
A10: Murilo Vargas da Silveira | B10: Coordenador Geral | C10: 45895
A11: Elaine Lima da Fonseca | B11: Coordenadora do eixo Relação e Mobilização Comunitária | C11: 45895
A12: Thiago Duarte Mielke | B12: Coordenador do eixo Agricultura Familiar | C12: 45895
A13: Leandro Cecílio Matte | B13: Coordenador de Assistência Técnica | C13: 45964
A14: Hedi Carlos Minin | B14: Coordenador do eixo Tecnologias da Informação e Comunicação | C14: 46086
A15: Giselly Juchnievski de Oliveira | B15: Coordenadora Administrativa | C15: -

Sheet Página3
A1: ASPROMEP
A2: ACLOLICAM
A3: ARME
A4: ACRZS
A5: APRERBRAL
A6: CISAN
A7: ASPRUB
A8: CISAN ASPROPALMAS
A9: ASPRUFAVI
A10: AGRILANÇA
A11: ASPROMOGG
A12: BEM-TE-VI
... A125: APCSA
